Ignoring exception in on_command_error
Traceback (most recent call last):
  File "/opt/virtualenvs/python3/lib/python3.8/site-packages/discord/ext/commands/core.py", line 85, in wrapped
    ret = await coro(*args, **kwargs)
  File "main.py", line 172, in add
    emoji = await ctx.guild.create_custom_emoji(name=name, image=image, reason=f"Added by {str(ctx.author)}")
  File "/opt/virtualenvs/python3/lib/python3.8/site-packages/discord/guild.py", line 1699, in create_custom_emoji
    data = await self._state.http.create_custom_emoji(self.id, name, img, roles=roles, reason=reason)
  File "/opt/virtualenvs/python3/lib/python3.8/site-packages/discord/http.py", line 247, in request
    raise HTTPException(r, data)
discord.errors.HTTPException: 400 Bad Request (error code: 50035): Invalid Form Body
In name: String value did not match validation regex.

The above exception was the direct cause of the following exception:

Traceback (most recent call last):
  File "/opt/virtualenvs/python3/lib/python3.8/site-packages/discord/client.py", line 343, in _run_event
    await coro(*args, **kwargs)
  File "main.py", line 90, in on_command_error
    raise error
  File "/opt/virtualenvs/python3/lib/python3.8/site-packages/discord/ext/commands/bot.py", line 902, in invoke
    await ctx.command.invoke(ctx)
  File "/opt/virtualenvs/python3/lib/python3.8/site-packages/discord/ext/commands/core.py", line 864, in invoke
    await injected(*ctx.args, **ctx.kwargs)
  File "/opt/virtualenvs/python3/lib/python3.8/site-packages/discord/ext/commands/core.py", line 94, in wrapped
    raise CommandInvokeError(exc) from exc
discord.ext.commands.errors.CommandInvokeError: Command raised an exception: HTTPException: 400 Bad Request (error code: 50035): Invalid Form Body
In name: String value did not match validation regex.
Exception ignored in: <function _SSLProtocolTransport.__del__ at 0x7f2f34f70b80>
Traceback (most recent call last):
  File "/usr/lib/python3.8/asyncio/sslproto.py", line 321, in __del__
    _warn(f"unclosed transport {self!r}", ResourceWarning, source=self)
ResourceWarning: unclosed transport <asyncio.sslproto._SSLProtocolTransport object at 0x7f2f1ea78400>
Exception ignored in: <function _SSLProtocolTransport.__del__ at 0x7f2f34f70b80>
Traceback (most recent call last):
  File "/usr/lib/python3.8/asyncio/sslproto.py", line 321, in __del__
    _warn(f"unclosed transport {self!r}", ResourceWarning, source=self)
ResourceWarning: unclosed transport <asyncio.sslproto._SSLProtocolTransport object at 0x7f2f1ea78340>

Exception ignored in: <function _SSLProtocolTransport.__del__ at 0x7f2f34f70b80>
Traceback (most recent call last):
  File "/usr/lib/python3.8/asyncio/sslproto.py", line 321, in __del__
    _warn(f"unclosed transport {self!r}", ResourceWarning, source=self)
ResourceWarning: unclosed transport <asyncio.sslproto._SSLProtocolTransport object at 0x7f2f1ea2a4c0>

